Omitir e ir al contenido
Historial del chat

Tú dijiste:
Imagen cargada
puedes darme el codigo escrito de esta imagen
ChatGPT Plus
¡Perfecto! 🚀 Aquí tienes el código escrito de la imagen que compartiste:

const request = new XMLHttpRequest();

request.open('GET', 'https://mi-api.com/recursos', true);

request.onload = function () {
  if (this.status >= 200 && this.status < 400) {
    // La solicitud ha tenido éxito
    const data = JSON.parse(this.response);
    console.log(data);
  } else {
    // Se ha producido un error al realizar la solicitud
  }
};

request.onerror = function () {
  // Se ha producido un error al realizar la solicitud
};

request.send();
¿Quieres que te lo explique paso por paso para principiantes, o prefieres que te lo reescriba usando fetch que es más moderno y sencillo?

Tú dijiste:
Imagen cargada
ahora de esta imagen
ChatGPT Plus
Aquí tienes el código escrito de la imagen que compartiste:

fetch('https://mi-api.com/recursos')
  .then(response => response.json())
  .then(data => console.log(data))
  .catch(error => console.error(error));
👉 Este ejemplo usa fetch, que es la forma moderna y más sencilla de hacer peticiones HTTP en JavaScript.

¿Quieres que te lo explique paso por paso comparándolo con el ejemplo anterior de XMLHttpRequest?

Tú dijiste:
Imagen cargada
ahora esta
ChatGPT Plus
Aquí tienes el código escrito de la imagen que compartiste con Axios:

axios.get('https://mi-api.com/recursos')
  .then(response => console.log(response.data))
  .catch(error => console.error(error));
👉 En este caso, se usa Axios, una librería muy popular para hacer peticiones HTTP.
La diferencia principal respecto a fetch es que Axios ya convierte automáticamente la respuesta a JSON, por eso accedemos directamente con response.data.

¿Quieres que te prepare una comparación clara entre los tres ejemplos (XMLHttpRequest, fetch y axios) para que veas cuál usar y cuándo?

Tú dijiste:
como declarar una function en try.catch en javascript
ChatGPT Plus
¡Muy buena pregunta! 🙌
En JavaScript, puedes usar un try...catch dentro de una función para manejar errores sin que tu programa se detenga.

Te muestro varias formas 👇

🔹 1. Función tradicional con try...catch
function dividir(a, b) {
  try {
    if (b === 0) {
      throw new Error("No se puede dividir entre 0");
    }
    return a / b;
  } catch (error) {
    console.error("Ocurrió un error:", error.message);
  }
}

console.log(dividir(10, 2)); // 5
console.log(dividir(10, 0)); // "Ocurrió un error: No se puede dividir entre 0"
🔹 2. Función flecha con try...catch
const dividir = (a, b) => {
  try {
    if (b === 0) throw new Error("No se puede dividir entre 0");
    return a / b;
  } catch (error) {
    console.error("Error:", error.message);
  }
};

console.log(dividir(8, 2)); // 4
console.log(dividir(8, 0)); // "Error: No se puede dividir entre 0"
🔹 3. Función asíncrona (async/await) con try...catch
Cuando trabajas con promesas (ejemplo: fetch o axios), es muy común usar try...catch.

async function obtenerDatos() {
  try {
    const response = await fetch("https://mi-api.com/recursos");
    const data = await response.json();
    console.log(data);
  } catch (error) {
    console.error("Error al obtener datos:", error.message);
  }
}

obtenerDatos();
👉 En resumen:

Dentro de cualquier función puedes usar try...catch.

Si la función es asíncrona, el try...catch captura errores de await.

Si es normal, captura errores síncronos (como divisiones inválidas).

¿Quieres que te prepare un ejemplo práctico con los tres estilos (normal, flecha y async) en un mismo archivo para que compares?

Tú dijiste:
damelo de una forma mas basica
ChatGPT Plus
¡Perfecto 👍! Vamos a lo más básico:

El try...catch sirve para intentar ejecutar un código (try) y si ocurre un error, lo captura (catch) sin que se rompa el programa.

Ejemplo básico con función normal:
function miFuncion() {
  try {
    let numero = 10 / 0; // Aquí ocurre un error lógico
    console.log("El resultado es:", numero);
  } catch (error) {
    console.log("Ocurrió un error:", error.message);
  }
}

miFuncion();
Ejemplo básico con función flecha:
const miFuncion = () => {
  try {
    let saludo = noExiste; // Error porque noExiste no está definido
    console.log(saludo);
  } catch (error) {
    console.log("Ocurrió un error:", error.message);
  }
};

miFuncion();
👉 En resumen:

try = intenta ejecutar el código.

catch = atrapa el error si pasa algo malo.

¿Quieres que te lo muestre con un ejemplo muy sencillo de la vida real (como dividir números o leer un dato que no existe) para que quede aún más claro?

Tú dijiste:
con el ejemplo de la division del principio
ChatGPT Plus
¡Perfecto! 🙌
Aquí te dejo el ejemplo más básico con una función de división usando try...catch:

function dividir(a, b) {
  try {
    if (b === 0) {
      throw new Error("No se puede dividir entre 0");
    }
    return a / b;
  } catch (error) {
    console.log("Ocurrió un error:", error.message);
  }
}

console.log(dividir(10, 2)); // 👉 5
console.log(dividir(10, 0)); // 👉 Ocurrió un error: No se puede dividir entre 0
🔎 Explicación rápida:

try: intenta ejecutar el código (la división).

throw new Error: lanza un error cuando b es 0.

catch: atrapa el error y lo muestra sin que el programa se rompa.

¿Quieres que te lo simplifique aún más quitando el throw y dejando solo un if dentro del try?



Ningún archivo seleccionadoNingún archivo seleccionado
ChatGPT puede cometer errores. Considera verificar la información importante.


¡Excelente! 🚀
Aquí tienes el mismo ejemplo pero todavía más simple, sin usar throw, solo con un if dentro del try:

function dividir(a, b) {
  try {
    if (b === 0) {
      console.log("No se puede dividir entre 0");
    } else {
      console.log("El resultado es:", a / b);
    }
  } catch (error) {
    console.log("Ocurrió un error:", error.message);
  }
}

dividir(10, 2); // 👉 El resultado es: 5
dividir(10, 0); // 👉 No se puede dividir entre 0


👉 Aquí el try atrapa cualquier error inesperado, pero el if ya evita el problema de dividir entre 0.

¿Quieres que te muestre la versión más mini (sin try...catch, solo con el if)?